<?xml version="1.0" encoding="utf-8"?>
<!-- This URDF was automatically created by SolidWorks to URDF Exporter! Originally created by Stephen Brawner (brawner@gmail.com) 
     Commit Version: 1.6.0-4-g7f85cfe  Build Version: 1.6.7995.38578
     For more information, please see http://wiki.ros.org/sw_urdf_exporter -->
<robot
  name="GP7 Robot.SLDASM">
  <link
    name="base_link">
    <inertial>
      <origin
        xyz="0.00557 0.094758 1.2548E-06"
        rpy="0 0 0" />
      <mass
        value="5.2154" />
      <inertia
        ixx="0.026026"
        ixy="-0.00013987"
        ixz="2.6039E-05"
        iyy="0.02172"
        iyz="-4.7704E-05"
        izz="0.025295" />
    </inertial>
    <visual>
      <origin
        xyz="0 0 0"
        rpy="0 0 0" />
      <geometry>
        <mesh
          filename="package://GP7 Robot.SLDASM/meshes/base_link.STL" />
      </geometry>
      <material
        name="">
        <color
          rgba="0.75294 0.75294 0.75294 1" />
      </material>
    </visual>
    <collision>
      <origin
        xyz="0 0 0"
        rpy="0 0 0" />
      <geometry>
        <mesh
          filename="package://GP7 Robot.SLDASM/meshes/base_link.STL" />
      </geometry>
    </collision>
  </link>
  <link
    name="link_1">
    <inertial>
      <origin
        xyz="0.00013451 0.099849 -0.015672"
        rpy="0 0 0" />
      <mass
        value="2.9447" />
      <inertia
        ixx="0.011947"
        ixy="-1.2249E-06"
        ixz="1.7024E-06"
        iyy="0.0088687"
        iyz="0.0021793"
        izz="0.011181" />
    </inertial>
    <visual>
      <origin
        xyz="0 0 0"
        rpy="0 0 0" />
      <geometry>
        <mesh
          filename="package://GP7 Robot.SLDASM/meshes/link_1.STL" />
      </geometry>
      <material
        name="">
        <color
          rgba="0.75294 0.75294 0.75294 1" />
      </material>
    </visual>
    <collision>
      <origin
        xyz="0 0 0"
        rpy="0 0 0" />
      <geometry>
        <mesh
          filename="package://GP7 Robot.SLDASM/meshes/link_1.STL" />
      </geometry>
    </collision>
  </link>
  <joint
    name="joint_1"
    type="revolute">
    <origin
      xyz="0 0 0.1901"
      rpy="1.5708 0 1.6133" />
    <parent
      link="base_link" />
    <child
      link="link_1" />
    <axis
      xyz="0 1 0" />
    <limit
      lower="-2.8984"
      upper="3.0357"
      effort="300"
      velocity="3" />
  </joint>
  <link
    name="link_2">
    <inertial>
      <origin
        xyz="0.027625 0.00020192 -0.19499"
        rpy="0 0 0" />
      <mass
        value="6.2406" />
      <inertia
        ixx="0.1263"
        ixy="4.2892E-05"
        ixz="-0.00019254"
        iyy="0.11052"
        iyz="0.00048286"
        izz="0.027757" />
    </inertial>
    <visual>
      <origin
        xyz="0 0 0"
        rpy="0 0 0" />
      <geometry>
        <mesh
          filename="package://GP7 Robot.SLDASM/meshes/link_2.STL" />
      </geometry>
      <material
        name="">
        <color
          rgba="0.75294 0.75294 0.75294 1" />
      </material>
    </visual>
    <collision>
      <origin
        xyz="0 0 0"
        rpy="0 0 0" />
      <geometry>
        <mesh
          filename="package://GP7 Robot.SLDASM/meshes/link_2.STL" />
      </geometry>
    </collision>
  </link>
  <joint
    name="joint_2"
    type="revolute">
    <origin
      xyz="0 0.1399 -0.04"
      rpy="3.1416 -1.4572 -1.5708" />
    <parent
      link="link_1" />
    <child
      link="link_2" />
    <axis
      xyz="0 1 0" />
    <limit
      lower="-1.0209"
      upper="2.2079"
      effort="200"
      velocity="3" />
  </joint>
  <link
    name="link_3">
    <inertial>
      <origin
        xyz="-0.015909 -0.00085391 0.020055"
        rpy="0 0 0" />
      <mass
        value="2.8492" />
      <inertia
        ixx="0.0082318"
        ixy="2.897E-05"
        ixz="-0.00090367"
        iyy="0.0077915"
        iyz="-3.8658E-05"
        izz="0.0069342" />
    </inertial>
    <visual>
      <origin
        xyz="0 0 0"
        rpy="0 0 0" />
      <geometry>
        <mesh
          filename="package://GP7 Robot.SLDASM/meshes/link_3.STL" />
      </geometry>
      <material
        name="">
        <color
          rgba="0.75294 0.75294 0.75294 1" />
      </material>
    </visual>
    <collision>
      <origin
        xyz="0 0 0"
        rpy="0 0 0" />
      <geometry>
        <mesh
          filename="package://GP7 Robot.SLDASM/meshes/link_3.STL" />
      </geometry>
    </collision>
  </link>
  <joint
    name="joint_3"
    type="revolute">
    <origin
      xyz="0 0 -0.445"
      rpy="3.1416 -0.11355 3.1416" />
    <parent
      link="link_2" />
    <child
      link="link_3" />
    <axis
      xyz="0 -1 0" />
    <limit
      lower="-1.3353"
      upper="3.2026"
      effort="200"
      velocity="3" />
  </joint>
  <link
    name="link_4">
    <inertial>
      <origin
        xyz="0.17354 -0.00015255 -0.00015965"
        rpy="0 0 0" />
      <mass
        value="2.7554" />
      <inertia
        ixx="0.0030857"
        ixy="3.9977E-06"
        ixz="-0.00031862"
        iyy="0.010085"
        iyz="-2.4876E-06"
        izz="0.010785" />
    </inertial>
    <visual>
      <origin
        xyz="0 0 0"
        rpy="0 0 0" />
      <geometry>
        <mesh
          filename="package://GP7 Robot.SLDASM/meshes/link_4.STL" />
      </geometry>
      <material
        name="">
        <color
          rgba="0.75294 0.75294 0.75294 1" />
      </material>
    </visual>
    <collision>
      <origin
        xyz="0 0 0"
        rpy="0 0 0" />
      <geometry>
        <mesh
          filename="package://GP7 Robot.SLDASM/meshes/link_4.STL" />
      </geometry>
    </collision>
  </link>
  <joint
    name="joint_4"
    type="revolute">
    <origin
      xyz="0.07223 0 0.04"
      rpy="-1.3963 0 0" />
    <parent
      link="link_3" />
    <child
      link="link_4" />
    <axis
      xyz="1 0 0" />
    <limit
      lower="-0.34907"
      upper="0"
      effort="200"
      velocity="3" />
  </joint>
  <link
    name="link_5">
    <inertial>
      <origin
        xyz="0.0002539 0.01321 -0.0017485"
        rpy="0 0 0" />
      <mass
        value="0.24589" />
      <inertia
        ixx="0.00013953"
        ixy="-2.1177E-06"
        ixz="1.9619E-07"
        iyy="0.00015684"
        iyz="-1.2921E-06"
        izz="0.00018562" />
    </inertial>
    <visual>
      <origin
        xyz="0 0 0"
        rpy="0 0 0" />
      <geometry>
        <mesh
          filename="package://GP7 Robot.SLDASM/meshes/link_5.STL" />
      </geometry>
      <material
        name="">
        <color
          rgba="0.75294 0.75294 0.75294 1" />
      </material>
    </visual>
    <collision>
      <origin
        xyz="0 0 0"
        rpy="0 0 0" />
      <geometry>
        <mesh
          filename="package://GP7 Robot.SLDASM/meshes/link_5.STL" />
      </geometry>
    </collision>
  </link>
  <joint
    name="joint_5"
    type="revolute">
    <origin
      xyz="0.36777 0 0"
      rpy="3.1416 0 1.4978" />
    <parent
      link="link_4" />
    <child
      link="link_5" />
    <axis
      xyz="0 0 1" />
    <limit
      lower="-2.2832"
      upper="2.4292"
      effort="200"
      velocity="3" />
  </joint>
  <link
    name="link_6">
    <inertial>
      <origin
        xyz="0.015638 -1.064E-11 -7.5295E-06"
        rpy="0 0 0" />
      <mass
        value="0.21473" />
      <inertia
        ixx="0.00031095"
        ixy="5.579E-14"
        ixz="2.0764E-09"
        iyy="0.00020913"
        iyz="-4.5256E-05"
        izz="0.00014711" />
    </inertial>
    <visual>
      <origin
        xyz="0 0 0"
        rpy="0 0 0" />
      <geometry>
        <mesh
          filename="package://GP7 Robot.SLDASM/meshes/link_6.STL" />
      </geometry>
      <material
        name="">
        <color
          rgba="0.75294 0.75294 0.75294 1" />
      </material>
    </visual>
    <collision>
      <origin
        xyz="0 0 0"
        rpy="0 0 0" />
      <geometry>
        <mesh
          filename="package://GP7 Robot.SLDASM/meshes/link_6.STL" />
      </geometry>
    </collision>
  </link>
  <joint
    name="joint_6"
    type="revolute">
    <origin
      xyz="0 0.069505 0"
      rpy="-2.9483 0 1.5708" />
    <parent
      link="link_5" />
    <child
      link="link_6" />
    <axis
      xyz="-1 0 0" />
    <limit
      lower="-3.3331"
      upper="2.9466"
      effort="200"
      velocity="3" />
  </joint>
  <link
    name="link_7">
    <inertial>
      <origin
        xyz="2.2204E-16 0.020964 0.0047329"
        rpy="0 0 0" />
      <mass
        value="0.14476" />
      <inertia
        ixx="9.9337E-05"
        ixy="-8.4703E-22"
        ixz="-2.1099E-19"
        iyy="0.00010865"
        iyz="-1.6659E-05"
        izz="5.7847E-05" />
    </inertial>
    <visual>
      <origin
        xyz="0 0 0"
        rpy="0 0 0" />
      <geometry>
        <mesh
          filename="package://GP7 Robot.SLDASM/meshes/link_7.STL" />
      </geometry>
      <material
        name="">
        <color
          rgba="0.79216 0.81961 0.93333 1" />
      </material>
    </visual>
    <collision>
      <origin
        xyz="0 0 0"
        rpy="0 0 0" />
      <geometry>
        <mesh
          filename="package://GP7 Robot.SLDASM/meshes/link_7.STL" />
      </geometry>
    </collision>
  </link>
  <joint
    name="joint_7"
    type="prismatic">
    <origin
      xyz="0.065495 -0.018092 -0.034338"
      rpy="-1.5708 0.48492 1.5708" />
    <parent
      link="link_6" />
    <child
      link="link_7" />
    <axis
      xyz="0 1 0" />
    <limit
      lower="0"
      upper="0.03"
      effort="100"
      velocity="3" />
  </joint>
  <link
    name="link_8">
    <inertial>
      <origin
        xyz="0 0.020964 0.0047329"
        rpy="0 0 0" />
      <mass
        value="0.14476" />
      <inertia
        ixx="9.9337E-05"
        ixy="1.0842E-19"
        ixz="7.3401E-20"
        iyy="0.00010865"
        iyz="-1.6659E-05"
        izz="5.7847E-05" />
    </inertial>
    <visual>
      <origin
        xyz="0 0 0"
        rpy="0 0 0" />
      <geometry>
        <mesh
          filename="package://GP7 Robot.SLDASM/meshes/link_8.STL" />
      </geometry>
      <material
        name="">
        <color
          rgba="0.79216 0.81961 0.93333 1" />
      </material>
    </visual>
    <collision>
      <origin
        xyz="0 0 0"
        rpy="0 0 0" />
      <geometry>
        <mesh
          filename="package://GP7 Robot.SLDASM/meshes/link_8.STL" />
      </geometry>
    </collision>
  </link>
  <joint
    name="joint_8"
    type="prismatic">
    <origin
      xyz="0.065495 0.018092 0.034338"
      rpy="1.5708 -0.48492 -1.5708" />
    <parent
      link="link_6" />
    <child
      link="link_8" />
    <axis
      xyz="0 -1 0" />
    <limit
      lower="-0.03"
      upper="0"
      effort="100"
      velocity="3" />
  </joint>
</robot>